Workbook

Sheet Summary Page
B2: Manager | C2: Greatland Realty Partner
B3: Entities | C3: Revlabs, Revlabspm
B4: Date | C4: 46053

Sheet 111100 PNC Cash
E2: Rev Labs Owner LLC PNC | Q2: 46155.414
D5: Bank Reconciliation Report
E7: 46047
E9: 1092223993
E11: Posted by: jlrr0627 on 2/1/2026
C14: Balance Per Bank Statement as of 1/25/2026 | L14: 1422016.6
C15: Outstanding Checks
C16: Check Date | G16: Check Number | I16: Payee | L16: Amount
C17: 46028 | G17: 2708 | I17: v0000663 - MacCormack Plumbing Inc. | L17: 1575
C18: 46028 | G18: 2712 | I18: v0000716 - Weston Ground Lessee LLC | L18: 7151.23
C19: 46036 | G19: 2713 | I19: v0000029 - Comcast | L19: 837.47
C20: 46036 | G20: 2715 | I20: v0000114 - SX BUSINESS SERVICES INC | L20: 439.36
C21: 46036 | G21: 2719 | I21: v0000324 - NATIONAL GRID | L21: 732.26
C22: 46036 | G22: 2721 | I22: v0000630 - Prudential Overall Supply | L22: 102.28
C23: 46042 | G23: 2722 | I23: v0000206 - DURKIN CO. INC. | L23: 215.42
C24: 46042 | G24: 2723 | I24: v0000298 - CADWELL DESIGN & SIGN | L24: 1021.66
C25: 46042 | G25: 2724 | I25: v0000301 - CINTAS | L25: 77.02
C26: 46042 | G26: 2725 | I26: v0000445 - Northeastern Mechanical Inc | L26: 2903.75
C27: 46042 | G27: 2726 | I27: v0000447 - Nalco Company LLC | L27: 1193.82
C28: 46042 | G28: 2727 | I28: v0000456 - J & M Brown Company | L28: 2714
... C33: 46042 | G33: 2733 | I33: v0000718 - Servus LLC | L33: 7578.99
C34: Less: | G34: Outstanding Checks | L34: 75027.61
G35: Reconciled Bank Balance | L35: 1346989
C37: Balance per GL as of 1/25/2026 | L37: 1346989
G38: Reconciled Balance Per G/L | L38: 1346989
C40: Difference | G40: (Reconciled Bank Balance And Reconciled Balance Per G/L) | L40: 0
B44: Cleared Items:
B47: Cleared Checks
B49: Date | F49: Tran # | H49: Notes | K49: Amount | M49: Date Cleared
B50: 46001 | F50: 2655 | H50: v0000166 - Janitronics Inc | K50: 7387.14 | M50: 46047
B51: 46001 | F51: 2669 | H51: v0000546 - TransAction Associates Inc | K51: 1318.96 | M51: 46047
B52: 46007 | F52: 2675 | H52: v0000061 - Greatland Realty Partners LLC | K52: 4174.6 | M52: 46047
B53: 46007 | F53: 2679 | H53: v0000397 - Prophia Inc | K53: 1500 | M53: 46047
B54: 46007 | F54: 2680 | H54: v0000441 - CINTAS CORPORATION | K54: 77.02 | M54: 46047
B55: 46028 | F55: 2684 | H55: v0000029 - Comcast | K55: 834.8 | M55: 46047
B56: 46028 | F56: 2685 | H56: v0000061 - Greatland Realty Partners LLC | K56: 32012.75 | M56: 46047
B57: 46028 | F57: 2686 | H57: v0000071 - Interconnect Computer Cabling | K57: 1676 | M57: 46047
B58: 46028 | F58: 2687 | H58: v0000073 - Jones Lang LaSalle Americas Inc | K58: 39778.83 | M58: 46047
B59: 46028 | F59: 2688 | H59: v0000145 - Verizon Wireless | K59: 306.41 | M59: 46047
B60: 46028 | F60: 2689 | H60: v0000154 - ArcLight Information Technology LLC | K60: 401.25 | M60: 46047
...

Sheet 111210 Cash - Development - Bof
D2: Revolution Labs Owner, LLC | L2: 46155.417
C5: Bank Reconciliation Report
D7: 46047
D9: 466007913132
D11: Posted by: jlrr0627 on 2/4/2026
B14: Balance Per Bank Statement as of 1/25/2026 | H14: 153410.1
E15: Reconciled Bank Balance | H15: 153410.1
B17: Balance per GL as of 1/25/2026 | H17: 153410.1
E18: Reconciled Balance Per G/L | H18: 153410.1
B20: Difference | E20: (Reconciled Bank Balance And Reconciled Balance Per G/L) | H20: 0

Sheet 115100 DACA
F2: Revlabpm Deposit account | R2: 46155.416
E5: Bank Reconciliation Report
F7: 46047
F9: 329681415132
F11: Posted by: jlrr0627 on 2/1/2026
D14: Balance Per Bank Statement as of 1/25/2026 | M14: 4375
H15: Reconciled Bank Balance | M15: 4375
D17: Balance per GL as of 1/25/2026 | M17: 4375
H18: Reconciled Balance Per G/L | M18: 4375
D20: Difference | H20: (Reconciled Bank Balance And Reconciled Balance Per G/L) | M20: 0
C25: Cleared Items:
C28: Cleared Deposits
C30: Date | G30: Tran # | I30: Notes | L30: Amount | N30: Date Cleared
C31: 46024 | G31: 134 | L31: 555863.01 | N31: 46047
C32: 46027 | G32: 133 | L32: 623273.65 | N32: 46047
C33: 46028 | G33: 135 | L33: 294162.71 | N33: 46047
C34: 46029 | G34: 136 | L34: 294162.71 | N34: 46047
C35: Total Cleared Deposits | L35: 1767462.1
C36: Cleared Other Items
C38: Date | G38: Tran # | I38: Notes | L38: Amount | N38: Date Cleared
C39: 46024 | G39: JE 18364 | I39: 01.02 Sweep | L39: -217871.54 | N39: 46047
C40: 46027 | G40: JE 18365 | I40: 01.05 Sweep | L40: -960640.12 | N40: 46047
C41: 46029 | G41: JE 18463 | I41: 01.07 Sweep | L41: -588325.42 | N41: 46047
C42: 46031 | G42: JE 18617 | I42: Record monthly bank fee | L42: -625 | N42: 46047
C43: Total Cleared Other Items | L43: -1767462.1

Sheet 115200 RET Escrow
B1: 115200
B2: RET Escrow
B3: revlabs | Period: Jan-2026 | Prepared: 05/12/2026
B5: Date | C5: Description | D5: Amount
C6: Balance Forward
B7: 03/25/2024 | C7: RET Escrow - Per statement due 4.10.24 | D7: 232339
B8: 05/24/2024 | C8: RET Escrow - Per statement due 5.10.24 | D8: 232339
B9: 06/25/2024 | C9: RET Escrow - Per statement due 6.10.24 | D9: 232339
B10: 07/25/2024 | C10: RET Escrow - Per statement due 7.10.24 | D10: 232339
B11: 07/25/2024 | C11: RET ESCROW Payment 8.1.24-2024 | D11: -680420.84
B12: 08/25/2024 | C12: RET Escrow - Per statement due 8.10.24 | D12: 232339
B13: 09/09/2024 | C13: RET Escrow - Per statement due 09.09.24 | D13: 216069.98
B14: 10/07/2024 | C14: RET Escrow - Per statement due 10.07.24 | D14: 216069.98
B15: 10/17/2024 | C15: RET ESCROW Payment 10.1.24-2024 | D15: -680420.84
B16: 11/07/2024 | C16: RET Escrow - Per statement due 11.07.24 | D16: 216069.98
B17: 12/09/2024 | C17: RET Escrow - Per statement due 12.09.24 | D17: 216069.98
B18: 01/07/2025 | C18: RET Escrow - Per statement due 01.07.25 | D18: 216069.98
... B35: 01/16/2026 | C35: RET ESCROW Payment 10.1.25-Q2-2025 | D35: -498750.81
B37: Ending Balance per GL | D37: =SUM(D7:D35)
B38: Ending Balance per TB | D38: =VLOOKUP(B1,'Trial Balance'!$A:$F,6,0)
B39: Variance | D39: =D37-D38

Sheet 115300 Insurance Escrow
B1: 115300
B2: Insurance Escrow
B3: revlabs | Period: Jan-2026 | Prepared: 05/12/2026
B5: Date | C5: Description | D5: Amount
C6: Balance Forward
B7: 04/25/2024 | C7: Property Insurance per 4.10.24 stmt due | D7: 23431
B8: 05/25/2024 | C8: Property Insurance per 5.10.24 stmt due | D8: 23431
B9: 06/25/2024 | C9: Property Insurance per 6.10.24 stmt due | D9: 23431
B10: 07/25/2024 | C10: Property Insurance per 7.10.24 stmt due | D10: 23431
B11: 08/25/2024 | C11: Property Insurance per 8.10.24 stmt due | D11: 23431
B12: 09/09/2024 | C12: Property Insurance per 9.09.24 stmt due | D12: 19280.11
B13: 10/07/2024 | C13: Property Insurance per 10.07.24 stmt due | D13: 19280.11
B14: 11/07/2024 | C14: Property Insurance per 11.07.24 stmt due | D14: 19280.11
B15: 12/09/2024 | C15: Property Insurance per 12.09.24 stmt due | D15: 19280.11
B16: 01/07/2025 | C16: Property Insurance per 01.07.25 stmt due | D16: 19280.11
B17: 02/07/2025 | C17: Property Insurance per 02.07.25 stmt due | D17: 19280.11
B18: 03/07/2025 | C18: Property Insurance per 03.07.25 stmt due | D18: 19280.11
... B27: 11/07/2025 | C27: Property Insurance per 11.08.25 stmt due | D27: 19280.11
B29: Ending Balance per GL | D29: =SUM(D7:D27)
B30: Ending Balance per TB | D30: =VLOOKUP(B1,'Trial Balance'!$A:$F,6,0)
B31: Variance | D31: =D29-D30

Sheet 115600 Loan Reserve
B1: 115600
B2: Loan Reserve
B3: revlabs | Period: Jan-2026 | Prepared: 05/12/2026
B5: Date | C5: Description | D5: Amount
C6: Balance Forward
B7: 03/25/2025 | C7: Rcd: Alchemab Lease Settlement Payment | D7: 4733004.4
B8: 03/25/2025 | C8: Rcd: 2/25 - 3/25 Interest Income | D8: 350.08
B9: 04/25/2025 | C9: Rcd: 04/25 Interest Income | D9: 265.48
B10: 05/25/2025 | C10: Rcd: 05/25 Interest Income | D10: 256.43
B11: 06/25/2025 | C11: Rcd: 06/25 Interest Income | D11: 238.29
B12: 07/25/2025 | C12: Rcd: 07/25 Interest Income | D12: 274.62
B13: 08/25/2025 | C13: Rcd: 08/25 Interest Income | D13: 238.31
B14: 09/25/2025 | C14: Rcd: 09/25 Interest Income | D14: 256.49
B15: 10/25/2025 | C15: Rcd: 10/25 Interest Income | D15: 256.5
B16: 11/25/2025 | C16: Rcd: 11/25 Interest Income | D16: 220.19
B17: 12/25/2025 | C17: Rcd: 12/25 Interest Income | D17: 283.78
B18: 01/25/2026 | C18: Rcd: 01/26 Interest Income | D18: 247.46
B20: Ending Balance per GL | D20: =SUM(D7:D18)
B21: Ending Balance per TB | D21: =VLOOKUP(B1,'Trial Balance'!$A:$F,6,0)
B22: Variance | D22: =D20-D21

Sheet 131100 AR Aging
A1: Aging Detail
A2: DB Caption: testgl 04/10/2026 Property: revlabpm Status: Current, Past, Future Age As Of: 01/31/2026 Post To: 01/2026
A3: Property | B3: Customer | C3: Lease | D3: Status | E3: Tran# | F3: Charge | G3: Date | H3: Month | I3: Current | J3: 0-30 | K3: 31-60 | L3: 61-90 | M3: Over | N3: Pre- | O3: Total
F4: Code | I4: Owed | J4: Owed | K4: Owed | L4: Owed | M4: 90 Owed | N4: payments | O4: Owed
A5: Revolution Labs Owner, LLC (revlabpm)
A6: Accent Therapeutics, Inc (t0000011)
A7: revlabpm | C7: Accent Therapeutics, Inc | D7: Current | E7: C-8760 | F7: ELECT | G7: 46045 | H7: 01/2026 | I7: 3325.87 | J7: 3325.87 | K7: 0 | L7: 0 | M7: 0 | N7: 0 | O7: 3325.87
A8: revlabpm | C8: Accent Therapeutics, Inc | D8: Current | E8: C-8761 | F8: ELECT | G8: 46045 | H8: 01/2026 | I8: 1771.69 | J8: 1771.69 | K8: 0 | L8: 0 | M8: 0 | N8: 0 | O8: 1771.69
A9: revlabpm | C9: Accent Therapeutics, Inc | D9: Current | E9: C-8764 | F9: UTILI | G9: 46045 | H9: 01/2026 | I9: 11.07 | J9: 11.07 | K9: 0 | L9: 0 | M9: 0 | N9: 0 | O9: 11.07
C10: Accent Therapeutics, Inc | I10: 5108.63 | J10: 5108.63 | K10: 0 | L10: 0 | M10: 0 | N10: 0 | O10: 5108.63
A12: Keros Therapeutics Inc (t0000013)
A13: revlabpm | C13: Keros Therapeutics Inc | D13: Current | E13: C-8758 | F13: ELECT | G13: 46045 | H13: 01/2026 | I13: 1298.13 | J13: 1298.13 | K13: 0 | L13: 0 | M13: 0 | N13: 0 | O13: 1298.13
A14: revlabpm | C14: Keros Therapeutics Inc | D14: Current | E14: C-8759 | F14: ELECT | G14: 46045 | H14: 01/2026 | I14: 6194.28 | J14: 6194.28 | K14: 0 | L14: 0 | M14: 0 | N14: 0 | O14: 6194.28
A15: revlabpm | C15: Keros Therapeutics Inc | D15: Current | E15: C-8765 | F15: UTILI | G15: 46045 | H15: 01/2026 | I15: 43.57 | J15: 43.57 | K15: 0 | L15: 0 | M15: 0 | N15: 0 | O15: 43.57
A16: revlabpm | C16: Keros Therapeutics Inc | D16: Current | E16: C-8766 | F16: UTILI | G16: 46045 | H16: 01/2026 | I16: 1581.94 | J16: 1581.94 | K16: 0 | L16: 0 | M16: 0 | N16: 0 | O16: 1581.94
C17: Keros Therapeutics Inc | I17: 9117.92 | J17: 9117.92 | K17: 0 | L17: 0 | M17: 0 | N17: 0 | O17: 9117.92
A19: Orum Therapeutics (t0000014)
A20: revlabpm | C20: Orum Therapeutics | D20: Current | E20: C-8762 | F20: ELECT | G20: 46045 | H20: 01/2026 | I20: 51.77 | J20: 51.77 | K20: 0 | L20: 0 | M20: 0 | N20: 0 | O20: 51.77
A21: revlabpm | C21: Orum Therapeutics | D21: Current | E21: C-8763 | F21: ELECT | G21: 46045 | H21: 01/2026 | I21: 652.03 | J21: 652.03 | K21: 0 | L21: 0 | M21: 0 | N21: 0 | O21: 652.03
A22: revlabpm | C22: Orum Therapeutics | D22: Current | E22: C-8767 | F22: UTILI | G22: 46045 | H22: 01/2026 | I22: 35.01 | J22: 35.01 | K22: 0 | L22: 0 | M22: 0 | N22: 0 | O22: 35.01
C23: Orum Therapeutics | I23: 738.81 | J23: 738.81 | K23: 0 | L23: 0 | M23: 0 | N23: 0 | O23: 738.81
A25: Santi Therapeutics Inc (t0000015)
A26: revlabpm | C26: Santi Therapeutics Inc | D26: Current | E26: R-4138 | F26: Prepay | G26: 46029 | H26: 01/2026 | I26: 0 | J26: 0 | K26: 0 | L26: 0 | M26: 0 | N26: -1273.83 | O26: -1273.83
A27: revlabpm | C27: Santi Therapeutics Inc | D27: Current | E27: R-4138 | F27: Prepay | G27: 46029 | H27: 01/2026 | I27: 0 | J27: 0 | K27: 0 | L27: 0 | M27: 0 | N27: -292888.88 | O27: -292888.88
A28: revlabpm | C28: Santi Therapeutics Inc | D28: Current | E28: C-8757 | F28: ELECT | G28: 46045 | H28: 01/2026 | I28: 2060.41 | J28: 2060.41 | K28: 0 | L28: 0 | M28: 0 | N28: 0 | O28: 2060.41
A29: revlabpm | C29: Santi Therapeutics Inc | D29: Current | E29: C-8768 | F29: UTILI | G29: 46045 | H29: 01/2026 | I29: 65.36 | J29: 65.36 | K29: 0 | L29: 0 | M29: 0 | N29: 0 | O29: 65.36
C30: Santi Therapeutics Inc | I30: 2125.77 | J30: 2125.77 | K30: 0 | L30: 0 | M30: 0 | N30: -294162.71 | O30: -292036.94
A32: revlabpm | I32: 17091.13 | J32: 17091.13 | K32: 0 | L32: 0 | M32: 0 | N32: -294162.71 | O32: -277071.58
A34: Grand Total | I34: 17091.13 | J34: 17091.13 | K34: 0 | L34: 0 | M34: 0 | N34: -294162.71 | O34: -277071.58
A36: UserId : rwalsh@greatlandpartners.com Date : 5/11/2026 Time : 8:04 AM

Sheet 133100 Accounts Receivable - Ot
B1: 133100
B2: Loan Reserve
B3: revlabs | Period: Jan-2026 | Prepared: 05/12/2026
B5: Date | C5: Description | D5: GL Account | E5: Amount
B8: Ending Balance per GL | E8: =SUM(E6:E7)
B9: Ending Balance per TB | E9: =VLOOKUP(B1,'Trial Balance'!$A:$F,6,0)
B10: Variance | E10: =E8-E9

Sheet 133110 AR Billback
B1: 133110
B2: AR Tenant Billback
B3: revlabs | Period: Jan-2026 | Prepared: 05/12/2026
B5: Date | C5: Description | D5: GL Account | E5: Amount
C6: Accrue: Keros Elect - 1/1/2026-1/31/2026 | D6: 440500 | E6: 5097.56
D7: 440500 | E7: 7492.41
D8: 440500 | E8: 703.8
D9: 440500 | E9: 2060.41
C10: Accrue: Keros HVAC - 1/1/2026-1/31/2026 | D10: 440700 | E10: 11.07
D11: 440700 | E11: 1625.51
D12: 440700 | E12: 35.01
D13: 440700 | E13: 65.36
B15: Ending Balance per GL | E15: =SUM(E6:E13)
B16: Ending Balance per TB | E16: =VLOOKUP(B1,'Trial Balance'!A:F,6,FALSE)
B17: Variance | E17: =E15-E16

Sheet RE Tax Analysis
B1: Revolution Labs
B2: RE Tax Analysis
B3: revlabs | Period: Jan-2026 | Prepared: 05/12/2026
B5: Description | C5: Date | D5: 135120 | E5: 641110
D6: Prepaid RE Taxes | E6: RE Tax Expense
B7: PARCEL ID: 00011619
B8: 3QTR Payment by client covering Jan thru March | C8: 01/25/2023 | D8: 796749.49
B9: Reclass January Tax Exp fr PPD | C9: 01/25/2023 | D9: -265583 | E9: 265583
B10: Reclass Feb Tax Exp fr PPD | C10: 02/25/2023 | D10: -265583 | E10: 265583
B11: Reclass Mar Tax Exp fr PPD | C11: 03/25/2023 | D11: -265583.49 | E11: 265583.49
B12: 4QTR Payment by client covering Apr thru June | C12: 04/25/2023 | D12: 796748.99
B13: Reclass April Tax Exp fr PPD | C13: 04/25/2023 | D13: -265583 | E13: 265583
B14: Reclass May Tax Exp fr PPD | C14: 05/25/2023 | D14: -265583 | E14: 265583
B15: Reclass June Tax Exp fr PPD | C15: 06/25/2023 | D15: -265582.99 | E15: 265582.99
B16: FY23/24 1QTR Payment covering July thru Sept | C16: 07/14/2023 | E16: 433692.41
B17: Reclass Aug and Sept Exp to PPD | C17: 07/25/2023 | D17: 289128.27 | E17: -289128.27
B18: Reclass Aug Tax Exp fr PPD | C18: 08/25/2023 | D18: -144564.14 | E18: 144564.14
B19: Reclass Sept Tax Exp fr PPD | C19: 09/25/2023 | D19: -144564.14 | E19: 144564.14
B20: Accr 9/23 Tax Increase | C20: 09/25/2023 | E20: 239204.01
B21: FY23/24 2QTR Payment covering Oct thru Dec-2023 | C21: 10/10/2023 | E21: 433692.41
B22: Reclass Nov and Dec -2023 Exp to PPD | C22: 10/25/2023 | D22: 289128.27 | E22: -289128.27
B23: Accr 10/23 Tax Increase | C23: 10/25/2023 | E23: 86935.84
B24: Reclass Nov Tax Exp fr PPD | C24: 11/25/2023 | D24: -144564.14 | E24: 144564.14
B25: Accr 11/23 Tax Increase | C25: 11/25/2023 | E25: 86935.84
B26: Reclass Dec Tax Exp fr PPD | C26: 12/25/2023 | D26: -144564.14 | E26: 144564.14
B27: Accr 12/23 Tax Increase | C27: 12/25/2023 | E27: 86935.84
B28: FY 24- Q3 Payment Covering Jan thru March 2024 | C28: 01/25/2024 | E28: 893567.25
B29: RE Tax Accrual Adjustment - Q3-FY24 | E29: -229943.16
B30: Reclass Feb -24 & March 24 | D30: 595711.5 | E30: -595711.5
B31: RE Tax Accrual Adjustment | D31: -153295.44 | E31: 153295.44
B32: Amortize Feb-24 RET Expense | D32: -297855.75 | E32: 297855.75
B33: Feb-24 Tax Accrual Adjustment | D33: 76647.72 | E33: -76647.72
B34: Amortize March-24 RET Expense | D34: -297855.75 | E34: 297855.75
B35: Reverse Feb accrual adj to zero out | D35: 76647.72 | E35: -76647.72
B36: FY 24- Q4 Payment Covering April thru June 2024 | C36: 04/05/2024 | E36: 893567.24
B37: Reclass May -24 & June 24 | D37: 595711.49 | E37: -595711.49
B38: RE Tax Accrual Adjustment - Q4-FY24 | D38: -229943.16
B39: RE Tax due per 5.10.24 Loan Stmt | D39: 76647.72 | E39: -76647.72
B40: Amortize 5.24 RET Expense (a) | D40: -297855.75 | E40: 297855.75
B41: Amortize Q3-FY24 Accrual Adjustment (a) | D41: 76647.72 | E41: -76647.72
...

Sheet Insurance Analysis
B1: Revolution Labs
B2: Insurance Analysis
B3: revlabs | Period: Jan-2026 | Prepared: 05/12/2026
B5: Policy Type / Description | C5: Term | D5: Total Premium | E5: Start Date | F5: End Date | G5: Per Month | H5: Months Amort. | I5: 639110 | J5: 639120 | K5: 135110
I6: Insurance - Property | J6: Insurance - General Liability | K6: Prepaid Insurance
B7: Property | C7: 6/12/2025- 6/12/2026 | D7: 48453.34 | E7: 45820 | F7: 46185 | G7: =D7/DATEDIF(E7,F7,"M") | H7: =IF(OR(E7="",F7=""),0,IF('Summary Page'!$C$4<E7,0,IF('Summary Page'!$C$4>=F7,D7,MIN(DATEDIF(DATE(YEAR(E7),MONTH(E7),1),'Summary Page'!$C$4,"M")+1,DATEDIF(E7,F7+1,"M"))*G7-IF(DAY(E7)>1,G7*(DAY(E7)-1)/DAY(EOMONTH(E7,0)),0)-IF('Summary Page'!$C$4>=DATE(YEAR(F7),MONTH(F7),1),IF(DAY(F7)<DAY(EOMONTH(F7,0)),G7*(DAY(EOMONTH(F7,0))-DAY(F7))/DAY(EOMONTH(F7,0)),0),0)))) | I7: =G7 | K7: =D7-H7
B8: General Liability | C8: 6/12/2025- 6/12/2026 | D8: 10456.67 | E8: 45820 | F8: 46185 | G8: =D8/DATEDIF(E8,F8,"M") | H8: =IF(OR(E8="",F8=""),0,IF('Summary Page'!$C$4<E8,0,IF('Summary Page'!$C$4>=F8,D8,MIN(DATEDIF(DATE(YEAR(E8),MONTH(E8),1),'Summary Page'!$C$4,"M")+1,DATEDIF(E8,F8+1,"M"))*G8-IF(DAY(E8)>1,G8*(DAY(E8)-1)/DAY(EOMONTH(E8,0)),0)-IF('Summary Page'!$C$4>=DATE(YEAR(F8),MONTH(F8),1),IF(DAY(F8)<DAY(EOMONTH(F8,0)),G8*(DAY(EOMONTH(F8,0))-DAY(F8))/DAY(EOMONTH(F8,0)),0),0)))) | J8: =G8 | K8: =D8-H8
B9: Umbrella Premium (CAN) | C9: 6/12/2025- 6/12/2026 | D9: 4282.12 | E9: 45820 | F9: 46185 | G9: =D9/DATEDIF(E9,F9,"M") | H9: =IF(OR(E9="",F9=""),0,IF('Summary Page'!$C$4<E9,0,IF('Summary Page'!$C$4>=F9,D9,MIN(DATEDIF(DATE(YEAR(E9),MONTH(E9),1),'Summary Page'!$C$4,"M")+1,DATEDIF(E9,F9+1,"M"))*G9-IF(DAY(E9)>1,G9*(DAY(E9)-1)/DAY(EOMONTH(E9,0)),0)-IF('Summary Page'!$C$4>=DATE(YEAR(F9),MONTH(F9),1),IF(DAY(F9)<DAY(EOMONTH(F9,0)),G9*(DAY(EOMONTH(F9,0))-DAY(F9))/DAY(EOMONTH(F9,0)),0),0)))) | I9: =G9 | K9: =D9-H9
B10: Umbrella Premium (Navigator) | C10: 6/12/2025- 6/12/2026 | D10: 3720.72 | E10: 45820 | F10: 46185 | G10: =D10/DATEDIF(E10,F10,"M") | H10: =IF(OR(E10="",F10=""),0,IF('Summary Page'!$C$4<E10,0,IF('Summary Page'!$C$4>=F10,D10,MIN(DATEDIF(DATE(YEAR(E10),MONTH(E10),1),'Summary Page'!$C$4,"M")+1,DATEDIF(E10,F10+1,"M"))*G10-IF(DAY(E10)>1,G10*(DAY(E10)-1)/DAY(EOMONTH(E10,0)),0)-IF('Summary Page'!$C$4>=DATE(YEAR(F10),MONTH(F10),1),IF(DAY(F10)<DAY(EOMONTH(F10,0)),G10*(DAY(EOMONTH(F10,0))-DAY(F10))/DAY(EOMONTH(F10,0)),0),0)))) | I10: =G10 | K10: =D10-H10
B12: Ending Balance per GL | I12: =SUM(I7:I11) | J12: =SUM(J7:J11) | K12: =SUM(K7:K11)
B13: Ending Balance per TB | I13: =VLOOKUP(I5,'Trial Balance'!$A:$F,6,0) | J13: =VLOOKUP(J5,'Trial Balance'!$A:$F,6,0) | K13: =VLOOKUP(K5,'Trial Balance'!$A:$F,6,0)
B14: Variance | I14: =I12-I13 | J14: =J12-J13 | K14: =K12-K13

Sheet Loan Analysis
B1: Revolution Labs
B2: Loan Analysis
B3: revlabs | Period: Jan-2026 | Prepared: 05/12/2026
B6: Date | C6: Loan # | D6: Description | E6: 231100 | F6: 213200 | G6: 801110
E7: Mortgage Payable | F7: Accrued Interest | G7: Interest Expense
D8: Balance at 12/31/24-Dec interest accrual | E8: -92104195 | F8: -701314.29
B9: 01/25 | D9: Dec 2024 Accrual Reversal | F9: 701314.29 | G9: -701314.29
B10: 01/25 | C10: 1159010 | D10: Dec Interest Payment | G10: 451630.77
B11: 01/25 | C11: 1159011 | D11: Dec Interest Payment | G11: 224715.17
B12: 01/25 | C12: 1159012 | D12: Dec Interest Payment | G12: 24968.35
B13: 01/25 | C13: 1159010 | D13: Accr Jan Interest Due -11159010 | F13: -440923.66 | G13: 440923.66
B14: 01/25 | C14: 1159011 | D14: Accr Jan Interest Due -11159011 | F14: -221503.04 | G14: 221503.04
B15: 01/25 | C15: 1159012 | D15: Accr Jan Interest Due -11159012 | F15: -24611.45 | G15: 24611.45
B16: 02/25 | D16: Jan 2025 Accrual Reversal | F16: 687038.15 | G16: -687038.15
B17: 02/25 | C17: 1159010 | D17: Jan Interest Payment | G17: 440923.66
B18: 02/25 | C18: 1159011 | D18: Jan Interest Payment | G18: 221503.04
B19: 02/25 | C19: 1159012 | D19: Jan Interest Payment | G19: 24611.45
B20: 02/25 | C20: 1159010 | D20: Accr Feb Interest Due -11159010 | F20: -398952.08 | G20: 398952.08
B21: 02/25 | C21: 1159011 | D21: Accr Feb Interest Due -11159011 | F21: -200276.8 | G21: 200276.8
B22: 02/25 | C22: 1159012 | D22: Accr Feb Interest Due -11159012 | F22: -22252.98 | G22: 22252.98
B23: 03/25 | D23: Feb 2025 Accrual Reversal | F23: 621481.86 | G23: -621481.86
B24: 03/25 | C24: 1159010 | D24: Feb Interest Payment | G24: 398952.08
B25: 03/25 | C25: 1159011 | D25: Feb Interest Payment | G25: 200276.8
B26: 03/25 | C26: 1159012 | D26: Feb Interest Payment | G26: 22252.98
B27: 03/25 | C27: 1159010 | D27: Accr Mar Interest Due -11159010 | F27: -442351.27 | G27: 442351.27
B28: 03/25 | C28: 1159011 | D28: Accr Mar Interest Due -11159011 | F28: -221931.32 | G28: 221931.32
B29: 03/25 | C29: 1159012 | D29: Accr Mar Interest Due -11159012 | F29: -24659.04 | G29: 24659.04
B30: 04/25 | D30: Mar 2025 Accrual Reversal | F30: 688941.63 | G30: -688941.63
B31: 04/25 | C31: 1159010 | D31: Mar Interest Payment | G31: 442351.27
B32: 04/25 | C32: 1159011 | D32: Mar Interest Payment | G32: 221931.32
B33: 04/25 | C33: 1159012 | D33: Mar Interest Payment | G33: 24659.04
B34: 04/25 | C34: 1159010 | D34: Accr April Interest Due -11159010 | F34: -426354.98 | G34: 426354.98
B35: 04/25 | C35: 1159011 | D35: Accr April Interest Due -11159011 | F35: -214254.16 | G35: 214254.16
B36: 04/25 | C36: 1159012 | D36: Accr April Interest Due -11159012 | F36: -23806.02 | G36: 23806.02
B37: 05/25 | D37: April 2025 Accrual Reversal | F37: 664415.16 | G37: -664415.16
B38: 05/25 | C38: 1159010 | D38: April Interest Payment | G38: 426354.92
B39: 05/25 | C39: 1159011 | D39: April Interest Payment | G39: 214254.16
B40: 05/25 | C40: 1159012 | D40: April Interest Payment | G40: 23806.02
B41: 05/25 | C41: 1159010 | D41: Accr May Interest Due -11159010 | F41: -443005.6 | G41: 443005.6
B42: 05/25 | C42: 1159011 | D42: Accr May Interest Due -11159011 | F42: -222127.62 | G42: 222127.62
...

Sheet 135150 PPD Other
B1: 135150
B2: Prepaid - Other
B3: revlabs | Period: Jan-2026 | Prepared: 05/12/2026
B5: Vendor | C5: Description | D5: Invoice Number | E5: Invoice Date | F5: G/L Account | G5: Start Date | H5: End Date | J5: Monthly Amt | K5: Months Amort. | L5: Remaining
B6: Greatland Realty Partners LLC | C6: Kardin Property Budgeting Software | D6: RevLabsKardin25 | E6: 45692 | F6: 637370 | G6: 45717 | H6: 46081 | I6: 992.58 | J6: =I6/DATEDIF(G6,H6+1,"M") | K6: =J6*DATEDIF(G6,'Summary Page'!$C$4+1,"M") | L6: =I6-K6
B7: Stewart Management Company | C7: Special Member Services | D7: 69655 | E7: 45748 | F7: 680110 | G7: 45748 | H7: 46112 | I7: 1500 | J7: =I7/DATEDIF(G7,H7+1,"M") | K7: =J7*DATEDIF(G7,'Summary Page'!$C$4+1,"M") | L7: =I7-K7
B8: Stewart Management Company | C8: Special Member Services | D8: 69656 | E8: 45748 | F8: 680110 | G8: 45748 | H8: 46112 | I8: 1500 | J8: =I8/DATEDIF(G8,H8+1,"M") | K8: =J8*DATEDIF(G8,'Summary Page'!$C$4+1,"M") | L8: =I8-K8
B9: CT CORPORATION SYSTEM | C9: Filing Fee | D9: 5009223719-01 | E9: 45778 | F9: 680110 | G9: 45809 | H9: 46173 | I9: 915.2 | J9: =I9/DATEDIF(G9,H9+1,"M") | K9: =J9*DATEDIF(G9,'Summary Page'!$C$4+1,"M") | L9: =I9-K9
B10: CT CORPORATION SYSTEM | C10: Filing Fee | D10: 5009224035-01 | E10: 45778 | F10: 680110 | G10: 45809 | H10: 46173 | I10: 607.6 | J10: =I10/DATEDIF(G10,H10+1,"M") | K10: =J10*DATEDIF(G10,'Summary Page'!$C$4+1,"M") | L10: =I10-K10
B11: CT CORPORATION SYSTEM | C11: Filing Fee | D11: 5009225232-1 | E11: 45778 | F11: 680110 | G11: 45809 | H11: 46173 | I11: 607.6 | J11: =I11/DATEDIF(G11,H11+1,"M") | K11: =J11*DATEDIF(G11,'Summary Page'!$C$4+1,"M") | L11: =I11-K11
B12: Dynamic Media | C12: Annula Streaming Service | D12: 1727601 | E12: 45870 | F12: 637330 | G12: 45901 | H12: 46265 | I12: 670.8 | J12: =I12/DATEDIF(G12,H12+1,"M") | K12: =J12*DATEDIF(G12,'Summary Page'!$C$4+1,"M") | L12: =I12-K12
B13: Prophia Inc | C13: Prophia Subscprition | D13: 3305 | E13: 45946 | F13: 680510 | G13: 45950 | H13: 46314 | I13: 1500 | J13: =I13/DATEDIF(G13,H13+1,"M") | K13: =J13*DATEDIF(G13,'Summary Page'!$C$4+1,"M") | L13: =I13-K13
B14: Apex Computers, Inc. | C14: Annual Firewall, Switch Wireless | D14: 128260 | E14: 46023 | F14: 637370 | G14: 46023 | H14: 46387 | I14: 3750 | J14: =I14/DATEDIF(G14,H14+1,"M") | K14: =J14*DATEDIF(G14,'Summary Page'!$C$4+1,"M") | L14: =I14-K14
B16: Ending Balance per GL | L16: =SUM(L6:L14)
B17: Ending Balance per TB | L17: =VLOOKUP(B1,'Trial Balance'!$A:$F,6,0)
B18: Variance | L18: =L16-L17

Sheet 141100 Due From-(To) Related Pa
B1: 141100
B2: Due From/(To) Related Parties
B3: revlabs | Period: Jan-2026 | Prepared by: Ryan Walsh | 05/12/2026
B5: Date | C5: Description | D5: Revlabs | E5: Revlabspm | F5: Total
F6: =SUM(D6:E6)
F7: =SUM(D7:E7)
B8: Ending Balance per GL | D8: =SUM(B6:B7) | E8: =SUM(C6:C7) | F8: =SUM(D6:D7)
B9: Ending Balance per TB | F9: =VLOOKUP(B1,'Trial Balance'!$A:$F,6,0)
B10: Variance | F10: =F8-F9

Sheet 152100 Land
B1: 152100
B2: Land
B3: revlabs | Period: Jan-2026 | Prepared: 05/12/2026
B5: Date | C5: Description | D5: Revlabs | E5: Revlabspm | F5: Total
B6: 12/31/2022 | C6: Move CIP Cost to FA - 12/14/2022 | D6: 29000000 | F6: =SUM(D6:E6)
B8: Ending Balance per GL | D8: =SUM(B5:B15) | E8: =SUM(C5:C6) | F8: =SUM(F6:F7)
B9: Ending Balance per TB | F9: =VLOOKUP(B1,'Trial Balance'!$A:$F,6,0)
B10: Variance | F10: =F8-F9

Sheet 154100 Building
B1: 154100
B2: Building
B3: revlabs | Period: Jan-2026 | Prepared: 05/12/2026
B5: Date | C5: Description | D5: Revlabs | E5: Revlabspm | F5: Total
B6: 01/01/2025 | C6: Beginning Balance (Revlabpm) | E6: 78897072 | F6: =SUM(D6:E6)
B7: 03/31/2025 | C7: Building Allocation (Revlabpm) | E7: 520.93 | F7: =SUM(D7:E7)
B8: 06/26/2025 | C8: Orum Q2 TI Capital (Revlabs) | D8: -10220.91 | F8: =SUM(D8:E8)
B10: Ending Balance per GL | F10: =SUM(F6:F8)
B11: Ending Balance per TB | F11: =VLOOKUP(B1,'Trial Balance'!$A:$F,6,0)
B12: Variance | F12: =F10-F11

Sheet 154500 Building Improvements
B1: 154500
B2: Building Improvements
B3: revlabs | Period: Jan-2026 | Prepared: 05/12/2026
B5: Date | C5: Description | D5: Revlabspm | E5: Revlabs | F5: Total
B6: 06/2024 | C6: Penthouse Floor Epoxy-Black Bear Coatings & Concrete | D6: 49570 | F6: =SUM(D6:E6)
B7: 06/2024 | C7: Electric Whip for Epoxy - S&W Electrical Contractors Inc. | D7: 705 | F7: =SUM(D7:E7)
B8: 02/2025 | C8: Garage Sports Equipment | D8: 12828.1 | F8: =SUM(D8:E8)
B9: 02/2025 | C9: 2nd Floor HVAC Corrections | D9: 33400 | F9: =SUM(D9:E9)
B11: Ending Balance per GL | F11: =SUM(F6:F9)
B12: Ending Balance per TB | F12: =VLOOKUP(B1,'Trial Balance'!$A:$F,6,0)
B13: Variance

Sheet 181200 Leasing Commissions
B1: 181200
B2: Leasing Commissions
B3: revlabs | Period: Jan-2026 | Prepared: 05/12/2026
B5: Commencement Date | C5: Description | D5: Revlabspm | E5: Revlabs | F5: Total
B6: 1/4/2023 - 11/30/2031 | C6: Keros | E6: 599121.6 | F6: =SUM(D6:E6)
B7: 4/13/2023 - 6/12/2033 | C7: Triana | E7: 638190 | F7: =SUM(D7:E7)
B8: 4/13/2023 - 6/12/2033 | C8: Accent | E8: 1365063 | F8: =SUM(D8:E8)
B9: 7/17/2023 - 8/31/2033 | C9: Orum | E9: 448665 | F9: =SUM(D9:E9)
B10: Moved-Out | C10: Alchemab | E10: 568260 | F10: =SUM(D10:E10)
B11: Rounding | E11: 0.4 | F11: =SUM(D11:E11)
B13: Ending Balance per GL | F13: =SUM(F6:F11)
B14: Ending Balance per TB | F14: =VLOOKUP(B1,'Trial Balance'!$A:$F,6,0)
B15: Variance | F15: =F13-F14

Sheet 181300 Legal Leasing Costs
B1: 181300
B2: Legal Leasing Costs
B3: revlabs | Period: Jan-2026 | Prepared: 05/12/2026
B5: Commencement Date | C5: Description | D5: Revlabspm | E5: Revlabs | F5: Total
B6: 1/4/2023 - 11/30/2031 | C6: Keros | E6: 48084.48 | F6: =SUM(D6:E6)
B7: 4/13/2023 - 6/12/2033 | C7: Triana | E7: 40976.04 | F7: =SUM(D7:E7)
B8: 4/13/2023 - 6/12/2033 | C8: Accent | E8: 92969.11 | F8: =SUM(D8:E8)
B9: 7/17/2023 - 8/31/2033 | C9: Orum | E9: 28807.27 | F9: =SUM(D9:E9)
B10: Moved-Out | C10: Alchemab | E10: 36486.06 | F10: =SUM(D10:E10)
B12: Ending Balance per GL | F12: =SUM(F6:F10)
B13: Ending Balance per TB | F13: =VLOOKUP(B1,'Trial Balance'!$A:$F,6,0)
B14: Variance | F14: =F12-F13

Sheet 181400 Tenant Improvement
B1: 181400
B2: Tenant Improvement
B3: revlabs | Period: Jan-2026 | Prepared: 05/12/2026
B5: Commencement Date | C5: Description | D5: Revlabspm | E5: Revlabs | F5: Total
B6: 1/4/2023 - 11/30/2031 | C6: Keros | E6: 6775780 | F6: =SUM(D6:E6)
B7: 4/13/2023 - 6/12/2033 | C7: Triana | E7: 6078000 | F7: =SUM(D7:E7)
B8: 4/13/2023 - 6/12/2033 | C8: Accent | E8: 12710805 | F8: =SUM(D8:E8)
B9: 7/17/2023 - 8/31/2033 | C9: Orum | E9: 4273000 | F9: =SUM(D9:E9)
B10: Moved-Out | C10: Alchemab | E10: 6375751.8 | F10: =SUM(D10:E10)
B12: Ending Balance per GL | F12: =SUM(F6:F10)
B13: Ending Balance per TB | F13: =VLOOKUP(B1,'Trial Balance'!$A:$F,6,0)
B14: Variance | F14: =F12-F13

Sheet 187100 Finance Costs
B1: 187100
B2: Finance Costs
B3: revlabs | Period: Jan-2026 | Prepared: 05/12/2026
B5: Date | C5: Description | D5: Revlabs | E5: Revlabpm | F5: Total
B6: 01/01/2024 | C6: Beginning Balance | D6: 0 | E6: 0 | F6: 0
B7: 10/31/2024 | C7: Rev Labs Extension Fee | D7: 230260.49 | E7: 0 | F7: 230260.49
B8: 06/25/2025 | C8: Frost Brown Todd LLP Invoice | D8: 3000 | E8: 0 | F8: 3000
B9: 06/25/2025 | C9: Berkadia Commercial Mortgage | D9: 230260.49 | E9: 0 | F9: 230260.49
B10: 06/25/2025 | C10: ACORE Capital, LP Invoice | D10: 1500 | E10: 0 | F10: 1500
B12: Ending Balance per GL | F12: =SUM(F6:F10)
B13: Ending Balance per TB | F13: =VLOOKUP(B1,'Trial Balance'!$A:$F,6,0)
B14: Variance | F14: 0

Sheet 211100 Accounts Payable - Contr
A1: Payables Aging Report
A2: revlabs revlabpm
A3: Period: 01/2026
A4: As of : 01/31/2026
A5: Payee | B5: Remittance Vendor | C5: Payee Name | D5: Invoice | E5: Control | F5: Batch Id | G5: Property | H5: Invoice Date | I5: Account | J5: Invoice # | K5: Current | L5: 0-30 | M5: 31-60 | N5: 61-90 | O5: Over | P5: Future | Q5: Notes
A6: Code | D6: Notes | K6: Owed | L6: Owed | M6: Owed | N6: Owed | O6: 90 | P6: Invoice
O7: Owed
A8: v0000073 | C8: Jones Lang LaSalle Americas Inc | P8: 0
E9: P-19527 | F9: 19094 | G9: revlabpm | H9: 46021 | I9: 637150 Admin-Tenant Relations | J9: USPAM513912 | K9: -1158.15 | L9: 0 | M9: -1158.15 | N9: 0 | O9: 0 | P9: 0 | Q9: 12.16.25 Recoverable Expenses
E10: P-19711 | F10: 19275 | G10: revlabpm | H10: 46031 | I10: 637110 Admin-Pay/Wages | J10: USPAM517721 | K10: -50237.93 | L10: -50237.93 | M10: 0 | N10: 0 | O10: 0 | P10: 0 | Q10: 12.25 Reimbursable Payroll
E11: P-19711 | F11: 19275 | G11: revlabpm | H11: 46031 | I11: 637150 Admin-Tenant Relations | J11: USPAM517721 | K11: 10073.5 | L11: 10073.5 | M11: 0 | N11: 0 | O11: 0 | P11: 0 | Q11: 11.25 Recoverable Expenses
E12: P-19737 | F12: 19301 | G12: revlabpm | H12: 46035 | I12: 637130 Admin-Management Fees | J12: USPAM519000 | K12: 14168.79 | L12: 14168.79 | M12: 0 | N12: 0 | O12: 0 | P12: 0 | Q12: 12/2025 JLL Mgmt Fee
E13: P-19738 | F13: 19302 | G13: revlabpm | H13: 46029 | I13: 615110 RM-Pay/Wages | J13: USPAM516039 | K13: 527.68 | L13: 527.68 | M13: 0 | N13: 0 | O13: 0 | P13: 0 | Q13: Eng OT 01.02.26
E14: P-19738 | F14: 19302 | G14: revlabpm | H14: 46029 | I14: 615110 RM-Pay/Wages | J14: USPAM516039 | K14: 14159.24 | L14: 14159.24 | M14: 0 | N14: 0 | O14: 0 | P14: 0 | Q14: Eng Payroll 01.02.26
E15: P-19738 | F15: 19302 | G15: revlabpm | H15: 46029 | I15: 637110 Admin-Pay/Wages | J15: USPAM516039 | K15: 7554.8 | L15: 7554.8 | M15: 0 | N15: 0 | O15: 0 | P15: 0 | Q15: Admin Payroll 01.02.26
A16: Total v0000073 | K16: -4912.07 | L16: -3753.92 | M16: -1158.15 | N16: 0 | O16: 0 | P16: 0
A18: Grand Total | K18: -4912.07 | L18: -3753.92 | M18: -1158.15 | N18: 0 | O18: 0 | P18: 0

Sheet 211300 Accounts Payable - Other
B1: 211300
B2: Accounts Payable - Other
B3: Period: Jan-2026 | revlabs | Prepared by: Ryan Walsh | 05/12/2026
B5: Date | C5: Description | D5: GL Account | E5: Amount
B8: Ending Balance per GL | E8: =SUM(E6:E7)
B9: Ending Balance per TB | E9: =VLOOKUP(B1,'Trial Balance'!$A:$F,6,0)
B10: Variance | E10: =E8-E9

Sheet 213100 Accr Exp
B1: 213100
B2: Accrued Expenses
B3: revlabs | Period: Jan-2026 | Prepared: 05/12/2026
B5: Date | C5: GL Account | D5: Description | E5: Vendor | F5: Amount
B6: 01/31/2026
B7: 01/31/2026
B8: 01/31/2026
B9: 01/31/2026
B10: 01/31/2026
B11: 01/31/2026
B12: 01/31/2026
B13: 01/31/2026
B15: Ending Balance per GL | F15: =SUM(F6:F13)
B16: Ending Balance per TB | F16: =VLOOKUP(B1,'Trial Balance'!$A:$F,6,0)
B17: Variance | F17: =F15-F16

Sheet 217200 Security Deposit - Other
B1: 217200
B2: Security Deposit - Other
B3: revlabs | Period: Jan-2026 | Prepared by: Ryan Walsh | 05/12/2026
B5: Date | C5: Description | D5: Revlabspm | E5: Revlabs | F5: Total
B6: 44439 | C6: 221335-Refundable Security Deposit | D6: -1000 | F6: =SUM(D6:E6)
B8: Ending Balance per GL | F8: =SUM(F6:F7)
B9: Ending Balance per TB | F9: =VLOOKUP(B1,'Trial Balance'!$A:$F,6,0)
B10: Variance | F10: =F8-F9

Sheet 221100 Prepaid Rent - Tenant
A1: Aging Detail
A2: DB Caption: testgl 04/10/2026 Property: revlabpm Status: Current, Past, Future Age As Of: 01/31/2026 Post To: 01/2026
A3: Property | B3: Customer | C3: Lease | D3: Status | E3: Tran# | F3: Charge | G3: Date | H3: Month | I3: Current | J3: 0-30 | K3: 31-60 | L3: 61-90 | M3: Over | N3: Pre- | O3: Total
F4: Code | I4: Owed | J4: Owed | K4: Owed | L4: Owed | M4: 90 Owed | N4: payments | O4: Owed
A5: Revolution Labs Owner, LLC (revlabpm)
A6: Accent Therapeutics, Inc (t0000011)
A7: revlabpm | C7: Accent Therapeutics, Inc | D7: Current | E7: C-8760 | F7: ELECT | G7: 46045 | H7: 01/2026 | I7: 3325.87 | J7: 3325.87 | K7: 0 | L7: 0 | M7: 0 | N7: 0 | O7: 3325.87
A8: revlabpm | C8: Accent Therapeutics, Inc | D8: Current | E8: C-8761 | F8: ELECT | G8: 46045 | H8: 01/2026 | I8: 1771.69 | J8: 1771.69 | K8: 0 | L8: 0 | M8: 0 | N8: 0 | O8: 1771.69
A9: revlabpm | C9: Accent Therapeutics, Inc | D9: Current | E9: C-8764 | F9: UTILI | G9: 46045 | H9: 01/2026 | I9: 11.07 | J9: 11.07 | K9: 0 | L9: 0 | M9: 0 | N9: 0 | O9: 11.07
C10: Accent Therapeutics, Inc | I10: 5108.63 | J10: 5108.63 | K10: 0 | L10: 0 | M10: 0 | N10: 0 | O10: 5108.63
A12: Keros Therapeutics Inc (t0000013)
A13: revlabpm | C13: Keros Therapeutics Inc | D13: Current | E13: C-8758 | F13: ELECT | G13: 46045 | H13: 01/2026 | I13: 1298.13 | J13: 1298.13 | K13: 0 | L13: 0 | M13: 0 | N13: 0 | O13: 1298.13
A14: revlabpm | C14: Keros Therapeutics Inc | D14: Current | E14: C-8759 | F14: ELECT | G14: 46045 | H14: 01/2026 | I14: 6194.28 | J14: 6194.28 | K14: 0 | L14: 0 | M14: 0 | N14: 0 | O14: 6194.28
A15: revlabpm | C15: Keros Therapeutics Inc | D15: Current | E15: C-8765 | F15: UTILI | G15: 46045 | H15: 01/2026 | I15: 43.57 | J15: 43.57 | K15: 0 | L15: 0 | M15: 0 | N15: 0 | O15: 43.57
A16: revlabpm | C16: Keros Therapeutics Inc | D16: Current | E16: C-8766 | F16: UTILI | G16: 46045 | H16: 01/2026 | I16: 1581.94 | J16: 1581.94 | K16: 0 | L16: 0 | M16: 0 | N16: 0 | O16: 1581.94
C17: Keros Therapeutics Inc | I17: 9117.92 | J17: 9117.92 | K17: 0 | L17: 0 | M17: 0 | N17: 0 | O17: 9117.92
A19: Orum Therapeutics (t0000014)
A20: revlabpm | C20: Orum Therapeutics | D20: Current | E20: C-8762 | F20: ELECT | G20: 46045 | H20: 01/2026 | I20: 51.77 | J20: 51.77 | K20: 0 | L20: 0 | M20: 0 | N20: 0 | O20: 51.77
A21: revlabpm | C21: Orum Therapeutics | D21: Current | E21: C-8763 | F21: ELECT | G21: 46045 | H21: 01/2026 | I21: 652.03 | J21: 652.03 | K21: 0 | L21: 0 | M21: 0 | N21: 0 | O21: 652.03
A22: revlabpm | C22: Orum Therapeutics | D22: Current | E22: C-8767 | F22: UTILI | G22: 46045 | H22: 01/2026 | I22: 35.01 | J22: 35.01 | K22: 0 | L22: 0 | M22: 0 | N22: 0 | O22: 35.01
C23: Orum Therapeutics | I23: 738.81 | J23: 738.81 | K23: 0 | L23: 0 | M23: 0 | N23: 0 | O23: 738.81
A25: Santi Therapeutics Inc (t0000015)
A26: revlabpm | C26: Santi Therapeutics Inc | D26: Current | E26: R-4138 | F26: Prepay | G26: 46029 | H26: 01/2026 | I26: 0 | J26: 0 | K26: 0 | L26: 0 | M26: 0 | N26: -1273.83 | O26: -1273.83
A27: revlabpm | C27: Santi Therapeutics Inc | D27: Current | E27: R-4138 | F27: Prepay | G27: 46029 | H27: 01/2026 | I27: 0 | J27: 0 | K27: 0 | L27: 0 | M27: 0 | N27: -292888.88 | O27: -292888.88
A28: revlabpm | C28: Santi Therapeutics Inc | D28: Current | E28: C-8757 | F28: ELECT | G28: 46045 | H28: 01/2026 | I28: 2060.41 | J28: 2060.41 | K28: 0 | L28: 0 | M28: 0 | N28: 0 | O28: 2060.41
A29: revlabpm | C29: Santi Therapeutics Inc | D29: Current | E29: C-8768 | F29: UTILI | G29: 46045 | H29: 01/2026 | I29: 65.36 | J29: 65.36 | K29: 0 | L29: 0 | M29: 0 | N29: 0 | O29: 65.36
C30: Santi Therapeutics Inc | I30: 2125.77 | J30: 2125.77 | K30: 0 | L30: 0 | M30: 0 | N30: -294162.71 | O30: -292036.94
A32: revlabpm | I32: 17091.13 | J32: 17091.13 | K32: 0 | L32: 0 | M32: 0 | N32: -294162.71 | O32: -277071.58
A34: Grand Total | I34: 17091.13 | J34: 17091.13 | K34: 0 | L34: 0 | M34: 0 | N34: -294162.71 | O34: -277071.58
A36: UserId : rwalsh@greatlandpartners.com Date : 5/11/2026 Time : 8:04 AM

Sheet 311100 Contributions-Partner A
B1: 311100
B2: Contributions - Partner A
B3: revlabs | Period: Jan-2026 | Prepared: 05/12/2026
B5: Date | C5: Description | D5: Revlabs | E5: Revlabpm | F5: Total
B6: 01/01/2025 | C6: Funding | D6: -80942266 | F6: =SUM(D6:E6)
B8: Ending Balance per GL | F8: =SUM(F2:F6)
B9: Ending Balance per TB | F9: =VLOOKUP(B1,'Trial Balance'!$A:$F,6,0)
B10: Variance | F10: =F8-F9

Sheet 331100 Distributions - A
B1: 331100
B2: Distributions - Partner A
B3: revlabs | Period: Jan-2026 | Prepared: 05/12/2026
B5: Date | C5: Description | D5: Revlabs | E5: Revlabpm | F5: Total
B6: 05/01/2021 | C6: 331100-Partner Distributions | D6: 19711731 | E6: 0 | F6: =SUM(D6:E6)
B7: 07/01/2024 | C7: Transfer to Rev Lab Ventures | D7: 0 | E7: 1250000 | F7: =SUM(D7:E7)
B8: 09/01/2024 | C8: Rcd: Distribution_09'24 - Transfer to Rev Lab Ventures | D8: 0 | E8: 2000000 | F8: =SUM(D8:E8)
B9: 12/01/2024 | C9: Rcd: Distribution_12'24 | D9: 0 | E9: 825000 | F9: =SUM(D9:E9)
B10: 03/01/2025 | C10: Rcd: Distribution_03'25 | D10: 0 | E10: 540000 | F10: =SUM(D10:E10)
B11: 08/01/2025 | C11: Rcd: Distribution_08'25 | D11: 0 | E11: 685000 | F11: =SUM(D11:E11)
B12: 09/01/2025 | C12: Rcd: Distribution_09'25 | D12: 0 | E12: 700000 | F12: =SUM(D12:E12)
B13: 12/01/2025 | C13: Rcd: Distribution_12'25 | D13: 0 | E13: 1025000 | F13: =SUM(D13:E13)
B15: Ending Balance per GL | F15: =SUM(F6:F13)
B16: Ending Balance per TB | F16: =VLOOKUP(B1,'Trial Balance'!$A:$F,6,0)
B17: Variance | F17: =F15-F16

Sheet 381100 Retained Earnings - C
B1: 381100
B2: Retained Earnings - Control
B3: revlabs | Period: Jan-2026 | Prepared: 05/12/2026
B5: Description | C5: Description | D5: Revlabpm | E5: Revlabs | F5: Total
B6: 46023 | C6: Beginning Balance | D6: -8184455.7 | E6: 251436.26 | F6: =SUM(D6:E6)
B8: Ending Balance per GL | F8: =SUM(F6:F7)
B9: Ending Balance per TB | F9: -7933019.5
B10: Variance | F10: 0

Sheet Trial Balance
A1: Property = revlabpm revlabs
A2: Trial Balance
A3: Period = Jan 2026
A4: Book = Accrual ; Tree = ysi_tb
C5: Forward | F5: Ending
C6: Balance | D6: Debit | E6: Credit | F6: Balance
A7: 111100 | B7: Cash - Operating | C7: 777307.24 | D7: 569681.8 | E7: 0 | F7: 1346989
A8: 111210 | B8: Cash - Development - BofA | C8: 153410.1 | D8: 0 | E8: 0 | F8: 153410.1
A9: 115100 | B9: Restricted Cash - Deposit Escrow | C9: 4375 | D9: 0 | E9: 0 | F9: 4375
A10: 115200 | B10: Restricted Cash - RE Tax Escrow | C10: 576594.68 | D10: 0 | E10: 295455.62 | F10: 281139.06
A11: 115300 | B11: Restricted Cash - Insurance Escrow | C11: 339443.8 | D11: 0 | E11: 0 | F11: 339443.8
A12: 115600 | B12: Restricted Cash - Other Reserve | C12: 4735644.5 | D12: 247.46 | E12: 0 | F12: 4735892
A13: 131100 | B13: Accounts Receivable - Control | C13: 361138.97 | D13: 0 | E13: 344047.84 | F13: 17091.13
A14: 133100 | B14: Accounts Receivable - Other | C14: 317248.52 | D14: 0 | E14: 317248.52 | F14: 0
A15: 133110 | B15: Accounts Receivable - Tenant Billback | C15: 12275.68 | D15: 4815.45 | E15: 0 | F15: 17091.13
A16: 135110 | B16: Prepaid Insurance | C16: 29924.92 | D16: 0 | E16: 5576.07 | F16: 24348.85
A17: 135120 | B17: Prepaid RE Tax | C17: 0 | D17: 332500.54 | E17: 0 | F17: 332500.54
A18: 135150 | B18: Prepaid Other | C18: 3421.27 | D18: 0 | E18: 1699.63 | F18: 1721.64
... A84: 801110 | B84: Interest Expense | C84: 0 | D84: 645399.37 | E84: 0 | F84: 645399.37
B85: Total | C85: 0 | D85: 2463596.5 | E85: 2463596.5 | F85: 0
